/home/ubuntu/venv_scvi/lib/python3.11/site-packages/scvi/data/fields/_dataframe_field.py:189: UserWarning: Category 2929 in adata.obs['_scvi_batch'] has fewer than 3 cells. Models may not train properly.
  categorical_mapping = _make_column_categorical(
Traceback (most recent call last):
  File "python/ray/_raylet.pyx", line 1364, in ray._raylet.execute_task.function_executor
  File "/home/ubuntu/venv_scvi/lib/python3.11/site-packages/ray/_private/function_manager.py", line 726, in actor_method_executor
    return method(__ray_actor, *args, **kwargs)
           ^^^^^^^^^^^^^^^^^^^^^^^^^^^^^^^^^^^^
  File "/home/ubuntu/venv_scvi/lib/python3.11/site-packages/ray/util/tracing/tracing_helper.py", line 464, in _resume_span
    return method(self, *_args, **_kwargs)
           ^^^^^^^^^^^^^^^^^^^^^^^^^^^^^^^
  File "/home/ubuntu/venv_scvi/lib/python3.11/site-packages/ray/tune/trainable/trainable.py", line 372, in train
    result = self.step()
             ^^^^^^^^^^^
  File "/home/ubuntu/venv_scvi/lib/python3.11/site-packages/ray/util/tracing/tracing_helper.py", line 464, in _resume_span
    return method(self, *_args, **_kwargs)
           ^^^^^^^^^^^^^^^^^^^^^^^^^^^^^^^
  File "/home/ubuntu/venv_scvi/lib/python3.11/site-packages/ray/tune/trainable/function_trainable.py", line 389, in step
    result = self._results_queue.get(
             ^^^^^^^^^^^^^^^^^^^^^^^^
  File "/usr/lib/python3.11/queue.py", line 180, in get
    self.not_empty.wait(remaining)
  File "/usr/lib/python3.11/threading.py", line 324, in wait
    gotit = waiter.acquire(True, timeout)
            ^^^^^^^^^^^^^^^^^^^^^^^^^^^^^
  File "/home/ubuntu/venv_scvi/lib/python3.11/site-packages/ray/_private/worker.py", line 776, in sigterm_handler
    sys.exit(1)
SystemExit: 1

During handling of the above exception, another exception occurred:

Traceback (most recent call last):
  File "python/ray/_raylet.pyx", line 1418, in ray._raylet.execute_task
  File "python/ray/_raylet.pyx", line 1501, in ray._raylet.execute_task
  File "/home/ubuntu/venv_scvi/lib/python3.11/site-packages/ray/_private/worker.py", line 569, in record_task_log_end
    self.core_worker.record_task_log_end(
    ^^^^^^^^^^^^^^^^
AttributeError: 'Worker' object has no attribute 'core_worker'

During handling of the above exception, another exception occurred:

Traceback (most recent call last):
  File "python/ray/_raylet.pyx", line 1787, in ray._raylet.task_execution_handler
  File "python/ray/_raylet.pyx", line 1684, in ray._raylet.execute_task_with_cancellation_handler
  File "python/ray/_raylet.pyx", line 1366, in ray._raylet.execute_task
  File "python/ray/_raylet.pyx", line 1367, in ray._raylet.execute_task
  File "python/ray/_raylet.pyx", line 1583, in ray._raylet.execute_task
  File "python/ray/_raylet.pyx", line 813, in ray._raylet.store_task_errors
AttributeError: 'Worker' object has no attribute 'core_worker'

During handling of the above exception, another exception occurred:

Traceback (most recent call last):
  File "python/ray/_raylet.pyx", line 1824, in ray._raylet.task_execution_handler
  File "/home/ubuntu/venv_scvi/lib/python3.11/site-packages/ray/_private/utils.py", line 174, in push_error_to_driver
    worker.core_worker.push_error(job_id, error_type, message, time.time())
    ^^^^^^^^^^^^^^^^^^
AttributeError: 'Worker' object has no attribute 'core_worker'
Exception ignored in: 'ray._raylet.task_execution_handler'
Traceback (most recent call last):
  File "python/ray/_raylet.pyx", line 1824, in ray._raylet.task_execution_handler
  File "/home/ubuntu/venv_scvi/lib/python3.11/site-packages/ray/_private/utils.py", line 174, in push_error_to_driver
    worker.core_worker.push_error(job_id, error_type, message, time.time())
    ^^^^^^^^^^^^^^^^^^
AttributeError: 'Worker' object has no attribute 'core_worker'
